Workbook

Sheet Scores
A1: Scientific name | B1: Common name | C1: VENOM HAZARD (0-100) | D1: Hazard rank | E1: HUMAN RISK (0-100) | F1: Risk rank | G1: Hazard data grade | H1: Flags | I1: Annual deaths (documented) | J1: Case-fatality rate | K1: Potency | L1: Quantity | M1: Encounter | N1: Bite propensity | O1: Onset | P1: Antivenom access | Q1: Risk dimensions used | R1: Species row
A2: Daboia russelii | B2: =IFERROR(INDEX(Species!$B$2:$B$300,$R2),"NOT IN SPECIES") -> Russell's viper | C2: =IF(w_pot+w_qty<=0,"",IF(AND(OR(w_pot=0,ISNUMBER(K2)),OR(w_qty=0,ISNUMBER(L2))),(w_pot*N(K2)+w_qty*N(L2))/(w_pot*ISNUMBER(K2)+w_qty*ISNUMBER(L2)),IF(ISNUMBER(K2),"needs yield","needs LD50"))) -> 89.924543 | D2: =IF(ISNUMBER(C2),RANK(C2,$C$2:$C$300),"") -> 1 | E2: =IF(w_enc+w_bite+w_onset+w_access<=0,"",IF(Q2<min_dims,"insufficient data",(w_enc*N(M2)+w_bite*N(N2)+w_onset*N(O2)+w_access*N(P2))/(w_enc*ISNUMBER(M2)+w_bite*ISNUMBER(N2)+w_onset*ISNUMBER(O2)+w_access*ISNUMBER(P2)))) -> 73.076923 | F2: =IF(ISNUMBER(E2),RANK(E2,$E$2:$E$300),"") -> 2 | G2: =IFERROR(IF(OR(INDEX(Species!$I$2:$I$300,$R2)="",INDEX(Species!$M$2:$M$300,$R2)=""),"",CHAR(MAX(CODE(INDEX(Species!$I$2:$I$300,$R2)),CODE(INDEX(Species!$M$2:$M$300,$R2))))),"") -> C | H2: =IFERROR(MID(IF(AND(ISNUMBER(INDEX(Species!$J$2:$J$300,$R2)),N(INDEX(Species!$J$2:$J$300,$R2))>1.5),"; LD50 sources differ "&TEXT(INDEX(Species!$J$2:$J$300,$R2),"0.0")&"x","")&IF(AND(INDEX(Species!$H$2:$H$300,$R2)<>"",INDEX(Species!$H$2:$H$300,$R2)<>"SC"),"; LD50 route "&INDEX(Species!$H$2:$H$300,$R2),"")&IF(INDEX(Species!$I$2:$I$300,$R2)="D","; LD50 Tier D","")&IF(AND(ISNUMBER(INDEX(Species!$N$2:$N$300,$R2)),N(INDEX(Species!$N$2:$N$300,$R2))>1.5),"; yield sources differ "&TEXT(INDEX(Species!$N$2:$N$300,$R2),"0.0")&"x","")&IF(INDEX(Species!$M$2:$M$300,$R2)="D","; yield Tier D",""),3,300),"") | I2: =IFERROR(INDEX(Species!$S$2:$S$300,$R2)&"","") | J2: =IFERROR(INDEX(Species!$T$2:$T$300,$R2)&"","") | K2: =IFERROR(MEDIAN(0,100*(LOG10(ld_least)-LOG10(INDEX(Species!$G$2:$G$300,$R2)))/(LOG10(ld_least)-LOG10(ld_most)),100),"") -> 100 | L2: =IFERROR(MEDIAN(0,100*(LOG10(INDEX(Species!$L$2:$L$300,$R2))-LOG10(y_min))/(LOG10(y_max)-LOG10(y_min)),100),"") -> 79.849085 | M2: =IFERROR(IF(ISNUMBER(INDEX(Species!$O$2:$O$300,$R2)),ord_floor+(ord_ceil-ord_floor)*(INDEX(Species!$O$2:$O$300,$R2)-1)/9,""),"") -> 90 | N2: =IFERROR(IF(ISNUMBER(INDEX(Species!$P$2:$P$300,$R2)),ord_floor+(ord_ceil-ord_floor)*(INDEX(Species!$P$2:$P$300,$R2)-1)/4,""),"") -> 90 | O2: =IFERROR(IF(ISNUMBER(INDEX(onset_ord,MATCH(INDEX(Species!$Q$2:$Q$300,$R2),onset_labels,0))),ord_floor+(ord_ceil-ord_floor)*(IF(onset_dir="mortality",6-INDEX(onset_ord,MATCH(INDEX(Species!$Q$2:$Q$300,$R2),onset_labels,0)),INDEX(onset_ord,MATCH(INDEX(Species!$Q$2:$Q$300,$R2),onset_labels,0)))-1)/4,""),"") -> 70 | P2: =IFERROR(IF(ISNUMBER(INDEX(access_ord,MATCH(INDEX(Species!$R$2:$R$300,$R2),access_labels,0))),ord_floor+(ord_ceil-ord_floor)*(INDEX(access_ord,MATCH(INDEX(Species!$R$2:$R$300,$R2),access_labels,0))-1)/4,""),"") -> 10 | Q2: =ISNUMBER(M2)*(w_enc>0)+ISNUMBER(N2)*(w_bite>0)+ISNUMBER(O2)*(w_onset>0)+ISNUMBER(P2)*(w_access>0) -> 4 | R2: =IFERROR(MATCH($A2,Species!$A$2:$A$300,0),"") -> 1
A3: Naja melanoleuca | B3: =IFERROR(INDEX(Species!$B$2:$B$300,$R3),"NOT IN SPECIES") -> Forest cobra | C3: =IF(w_pot+w_qty<=0,"",IF(AND(OR(w_pot=0,ISNUMBER(K3)),OR(w_qty=0,ISNUMBER(L3))),(w_pot*N(K3)+w_qty*N(L3))/(w_pot*ISNUMBER(K3)+w_qty*ISNUMBER(L3)),IF(ISNUMBER(K3),"needs yield","needs LD50"))) -> 89.652714 | D3: =IF(ISNUMBER(C3),RANK(C3,$C$2:$C$300),"") -> 2 | E3: =IF(w_enc+w_bite+w_onset+w_access<=0,"",IF(Q3<min_dims,"insufficient data",(w_enc*N(M3)+w_bite*N(N3)+w_onset*N(O3)+w_access*N(P3))/(w_enc*ISNUMBER(M3)+w_bite*ISNUMBER(N3)+w_onset*ISNUMBER(O3)+w_access*ISNUMBER(P3)))) -> 33.760684 | F3: =IF(ISNUMBER(E3),RANK(E3,$E$2:$E$300),"") -> 73 | G3: =IFERROR(IF(OR(INDEX(Species!$I$2:$I$300,$R3)="",INDEX(Species!$M$2:$M$300,$R3)=""),"",CHAR(MAX(CODE(INDEX(Species!$I$2:$I$300,$R3)),CODE(INDEX(Species!$M$2:$M$300,$R3))))),"") -> C | H3: =IFERROR(MID(IF(AND(ISNUMBER(INDEX(Species!$J$2:$J$300,$R3)),N(INDEX(Species!$J$2:$J$300,$R3))>1.5),"; LD50 sources differ "&TEXT(INDEX(Species!$J$2:$J$300,$R3),"0.0")&"x","")&IF(AND(INDEX(Species!$H$2:$H$300,$R3)<>"",INDEX(Species!$H$2:$H$300,$R3)<>"SC"),"; LD50 route "&INDEX(Species!$H$2:$H$300,$R3),"")&IF(INDEX(Species!$I$2:$I$300,$R3)="D","; LD50 Tier D","")&IF(AND(ISNUMBER(INDEX(Species!$N$2:$N$300,$R3)),N(INDEX(Species!$N$2:$N$300,$R3))>1.5),"; yield sources differ "&TEXT(INDEX(Species!$N$2:$N$300,$R3),"0.0")&"x","")&IF(INDEX(Species!$M$2:$M$300,$R3)="D","; yield Tier D",""),3,300),"") -> LD50 sources differ 1.9x; yield sources differ 2.2x | I3: =IFERROR(INDEX(Species!$S$2:$S$300,$R3)&"","") | J3: =IFERROR(INDEX(Species!$T$2:$T$300,$R3)&"","") | K3: =IFERROR(MEDIAN(0,100*(LOG10(ld_least)-LOG10(INDEX(Species!$G$2:$G$300,$R3)))/(LOG10(ld_least)-LOG10(ld_most)),100),"") -> 79.305428 | L3: =IFERROR(MEDIAN(0,100*(LOG10(INDEX(Species!$L$2:$L$300,$R3))-LOG10(y_min))/(LOG10(y_max)-LOG10(y_min)),100),"") -> 100 | M3: =IFERROR(IF(ISNUMBER(INDEX(Species!$O$2:$O$300,$R3)),ord_floor+(ord_ceil-ord_floor)*(INDEX(Species!$O$2:$O$300,$R3)-1)/9,""),"") -> 27.777778 | N3: =IFERROR(IF(ISNUMBER(INDEX(Species!$P$2:$P$300,$R3)),ord_floor+(ord_ceil-ord_floor)*(INDEX(Species!$P$2:$P$300,$R3)-1)/4,""),"") -> 50 | O3: =IFERROR(IF(ISNUMBER(INDEX(onset_ord,MATCH(INDEX(Species!$Q$2:$Q$300,$R3),onset_labels,0))),ord_floor+(ord_ceil-ord_floor)*(IF(onset_dir="mortality",6-INDEX(onset_ord,MATCH(INDEX(Species!$Q$2:$Q$300,$R3),onset_labels,0)),INDEX(onset_ord,MATCH(INDEX(Species!$Q$2:$Q$300,$R3),onset_labels,0)))-1)/4,""),"") -> 30 | P3: =IFERROR(IF(ISNUMBER(INDEX(access_ord,MATCH(INDEX(Species!$R$2:$R$300,$R3),access_labels,0))),ord_floor+(ord_ceil-ord_floor)*(INDEX(access_ord,MATCH(INDEX(Species!$R$2:$R$300,$R3),access_labels,0))-1)/4,""),"") -> 30 | Q3: =ISNUMBER(M3)*(w_enc>0)+ISNUMBER(N3)*(w_bite>0)+ISNUMBER(O3)*(w_onset>0)+ISNUMBER(P3)*(w_access>0) -> 4 | R3: =IFERROR(MATCH($A3,Species!$A$2:$A$300,0),"") -> 52
A4: Oxyuranus microlepidotus | B4: =IFERROR(INDEX(Species!$B$2:$B$300,$R4),"NOT IN SPECIES") -> Inland taipan | C4: =IF(w_pot+w_qty<=0,"",IF(AND(OR(w_pot=0,ISNUMBER(K4)),OR(w_qty=0,ISNUMBER(L4))),(w_pot*N(K4)+w_qty*N(L4))/(w_pot*ISNUMBER(K4)+w_qty*ISNUMBER(L4)),IF(ISNUMBER(K4),"needs yield","needs LD50"))) -> 84.348409 | D4: =IF(ISNUMBER(C4),RANK(C4,$C$2:$C$300),"") -> 4 | E4: =IF(w_enc+w_bite+w_onset+w_access<=0,"",IF(Q4<min_dims,"insufficient data",(w_enc*N(M4)+w_bite*N(N4)+w_onset*N(O4)+w_access*N(P4))/(w_enc*ISNUMBER(M4)+w_bite*ISNUMBER(N4)+w_onset*ISNUMBER(O4)+w_access*ISNUMBER(P4)))) -> 14.615385 | F4: =IF(ISNUMBER(E4),RANK(E4,$E$2:$E$300),"") -> 91 | G4: =IFERROR(IF(OR(INDEX(Species!$I$2:$I$300,$R4)="",INDEX(Species!$M$2:$M$300,$R4)=""),"",CHAR(MAX(CODE(INDEX(Species!$I$2:$I$300,$R4)),CODE(INDEX(Species!$M$2:$M$300,$R4))))),"") -> B | H4: =IFERROR(MID(IF(AND(ISNUMBER(INDEX(Species!$J$2:$J$300,$R4)),N(INDEX(Species!$J$2:$J$300,$R4))>1.5),"; LD50 sources differ "&TEXT(INDEX(Species!$J$2:$J$300,$R4),"0.0")&"x","")&IF(AND(INDEX(Species!$H$2:$H$300,$R4)<>"",INDEX(Species!$H$2:$H$300,$R4)<>"SC"),"; LD50 route "&INDEX(Species!$H$2:$H$300,$R4),"")&IF(INDEX(Species!$I$2:$I$300,$R4)="D","; LD50 Tier D","")&IF(AND(ISNUMBER(INDEX(Species!$N$2:$N$300,$R4)),N(INDEX(Species!$N$2:$N$300,$R4))>1.5),"; yield sources differ "&TEXT(INDEX(Species!$N$2:$N$300,$R4),"0.0")&"x","")&IF(INDEX(Species!$M$2:$M$300,$R4)="D","; yield Tier D",""),3,300),"") | I4: =IFERROR(INDEX(Species!$S$2:$S$300,$R4)&"","") -> 0 (Australia, 2005-2015) | J4: =IFERROR(INDEX(Species!$T$2:$T$300,$R4)&"","") | K4: =IFERROR(MEDIAN(0,100*(LOG10(ld_least)-LOG10(INDEX(Species!$G$2:$G$300,$R4)))/(LOG10(ld_least)-LOG10(ld_most)),100),"") -> 100 | L4: =IFERROR(MEDIAN(0,100*(LOG10(INDEX(Species!$L$2:$L$300,$R4))-LOG10(y_min))/(LOG10(y_max)-LOG10(y_min)),100),"") -> 68.696817 | M4: =IFERROR(IF(ISNUMBER(INDEX(Species!$O$2:$O$300,$R4)),ord_floor+(ord_ceil-ord_floor)*(INDEX(Species!$O$2:$O$300,$R4)-1)/9,""),"") -> 10 | N4: =IFERROR(IF(ISNUMBER(INDEX(Species!$P$2:$P$300,$R4)),ord_floor+(ord_ceil-ord_floor)*(INDEX(Species!$P$2:$P$300,$R4)-1)/4,""),"") -> 30 | O4: =IFERROR(IF(ISNUMBER(INDEX(onset_ord,MATCH(INDEX(Species!$Q$2:$Q$300,$R4),onset_labels,0))),ord_floor+(ord_ceil-ord_floor)*(IF(onset_dir="mortality",6-INDEX(onset_ord,MATCH(INDEX(Species!$Q$2:$Q$300,$R4),onset_labels,0)),INDEX(onset_ord,MATCH(INDEX(Species!$Q$2:$Q$300,$R4),onset_labels,0)))-1)/4,""),"") -> 10 | P4: =IFERROR(IF(ISNUMBER(INDEX(access_ord,MATCH(INDEX(Species!$R$2:$R$300,$R4),access_labels,0))),ord_floor+(ord_ceil-ord_floor)*(INDEX(access_ord,MATCH(INDEX(Species!$R$2:$R$300,$R4),access_labels,0))-1)/4,""),"") -> 10 | Q4: =ISNUMBER(M4)*(w_enc>0)+ISNUMBER(N4)*(w_bite>0)+ISNUMBER(O4)*(w_onset>0)+ISNUMBER(P4)*(w_access>0) -> 4 | R4: =IFERROR(MATCH($A4,Species!$A$2:$A$300,0),"") -> 5
A5: Oxyuranus scutellatus | B5: =IFERROR(INDEX(Species!$B$2:$B$300,$R5),"NOT IN SPECIES") -> Coastal taipan | C5: =IF(w_pot+w_qty<=0,"",IF(AND(OR(w_pot=0,ISNUMBER(K5)),OR(w_qty=0,ISNUMBER(L5))),(w_pot*N(K5)+w_qty*N(L5))/(w_pot*ISNUMBER(K5)+w_qty*ISNUMBER(L5)),IF(ISNUMBER(K5),"needs yield","needs LD50"))) -> 84.524485 | D5: =IF(ISNUMBER(C5),RANK(C5,$C$2:$C$300),"") -> 3 | E5: =IF(w_enc+w_bite+w_onset+w_access<=0,"",IF(Q5<min_dims,"insufficient data",(w_enc*N(M5)+w_bite*N(N5)+w_onset*N(O5)+w_access*N(P5))/(w_enc*ISNUMBER(M5)+w_bite*ISNUMBER(N5)+w_onset*ISNUMBER(O5)+w_access*ISNUMBER(P5)))) -> 37.521368 | F5: =IF(ISNUMBER(E5),RANK(E5,$E$2:$E$300),"") -> 63 | G5: =IFERROR(IF(OR(INDEX(Species!$I$2:$I$300,$R5)="",INDEX(Species!$M$2:$M$300,$R5)=""),"",CHAR(MAX(CODE(INDEX(Species!$I$2:$I$300,$R5)),CODE(INDEX(Species!$M$2:$M$300,$R5))))),"") -> C | H5: =IFERROR(MID(IF(AND(ISNUMBER(INDEX(Species!$J$2:$J$300,$R5)),N(INDEX(Species!$J$2:$J$300,$R5))>1.5),"; LD50 sources differ "&TEXT(INDEX(Species!$J$2:$J$300,$R5),"0.0")&"x","")&IF(AND(INDEX(Species!$H$2:$H$300,$R5)<>"",INDEX(Species!$H$2:$H$300,$R5)<>"SC"),"; LD50 route "&INDEX(Species!$H$2:$H$300,$R5),"")&IF(INDEX(Species!$I$2:$I$300,$R5)="D","; LD50 Tier D","")&IF(AND(ISNUMBER(INDEX(Species!$N$2:$N$300,$R5)),N(INDEX(Species!$N$2:$N$300,$R5))>1.5),"; yield sources differ "&TEXT(INDEX(Species!$N$2:$N$300,$R5),"0.0")&"x","")&IF(INDEX(Species!$M$2:$M$300,$R5)="D","; yield Tier D",""),3,300),"") | I5: =IFERROR(INDEX(Species!$S$2:$S$300,$R5)&"","") | J5: =IFERROR(INDEX(Species!$T$2:$T$300,$R5)&"","") | K5: =IFERROR(MEDIAN(0,100*(LOG10(ld_least)-LOG10(INDEX(Species!$G$2:$G$300,$R5)))/(LOG10(ld_least)-LOG10(ld_most)),100),"") -> 82.815316 | L5: =IFERROR(MEDIAN(0,100*(LOG10(INDEX(Species!$L$2:$L$300,$R5))-LOG10(y_min))/(LOG10(y_max)-LOG10(y_min)),100),"") -> 86.233653 | M5: =IFERROR(IF(ISNUMBER(INDEX(Species!$O$2:$O$300,$R5)),ord_floor+(ord_ceil-ord_floor)*(INDEX(Species!$O$2:$O$300,$R5)-1)/9,""),"") -> 45.555556 | N5: =IFERROR(IF(ISNUMBER(INDEX(Species!$P$2:$P$300,$R5)),ord_floor+(ord_ceil-ord_floor)*(INDEX(Species!$P$2:$P$300,$R5)-1)/4,""),"") -> 50 | O5: =IFERROR(IF(ISNUMBER(INDEX(onset_ord,MATCH(INDEX(Species!$Q$2:$Q$300,$R5),onset_labels,0))),ord_floor+(ord_ceil-ord_floor)*(IF(onset_dir="mortality",6-INDEX(onset_ord,MATCH(INDEX(Species!$Q$2:$Q$300,$R5),onset_labels,0)),INDEX(onset_ord,MATCH(INDEX(Species!$Q$2:$Q$300,$R5),onset_labels,0)))-1)/4,""),"") -> 30 | P5: =IFERROR(IF(ISNUMBER(INDEX(access_ord,MATCH(INDEX(Species!$R$2:$R$300,$R5),access_labels,0))),ord_floor+(ord_ceil-ord_floor)*(INDEX(access_ord,MATCH(INDEX(Species!$R$2:$R$300,$R5),access_labels,0))-1)/4,""),"") -> 10 | Q5: =ISNUMBER(M5)*(w_enc>0)+ISNUMBER(N5)*(w_bite>0)+ISNUMBER(O5)*(w_onset>0)+ISNUMBER(P5)*(w_access>0) -> 4 | R5: =IFERROR(MATCH($A5,Species!$A$2:$A$300,0),"") -> 3
A6: Bitis gabonica | B6: =IFERROR(INDEX(Species!$B$2:$B$300,$R6),"NOT IN SPECIES") -> Gaboon viper | C6: =IF(w_pot+w_qty<=0,"",IF(AND(OR(w_pot=0,ISNUMBER(K6)),OR(w_qty=0,ISNUMBER(L6))),(w_pot*N(K6)+w_qty*N(L6))/(w_pot*ISNUMBER(K6)+w_qty*ISNUMBER(L6)),IF(ISNUMBER(K6),"needs yield","needs LD50"))) -> 84.117211 | D6: =IF(ISNUMBER(C6),RANK(C6,$C$2:$C$300),"") -> 5 | E6: =IF(w_enc+w_bite+w_onset+w_access<=0,"",IF(Q6<min_dims,"insufficient data",(w_enc*N(M6)+w_bite*N(N6)+w_onset*N(O6)+w_access*N(P6))/(w_enc*ISNUMBER(M6)+w_bite*ISNUMBER(N6)+w_onset*ISNUMBER(O6)+w_access*ISNUMBER(P6)))) -> 42.991453 | F6: =IF(ISNUMBER(E6),RANK(E6,$E$2:$E$300),"") -> 47 | G6: =IFERROR(IF(OR(INDEX(Species!$I$2:$I$300,$R6)="",INDEX(Species!$M$2:$M$300,$R6)=""),"",CHAR(MAX(CODE(INDEX(Species!$I$2:$I$300,$R6)),CODE(INDEX(Species!$M$2:$M$300,$R6))))),"") -> C | H6: =IFERROR(MID(IF(AND(ISNUMBER(INDEX(Species!$J$2:$J$300,$R6)),N(INDEX(Species!$J$2:$J$300,$R6))>1.5),"; LD50 sources differ "&TEXT(INDEX(Species!$J$2:$J$300,$R6),"0.0")&"x","")&IF(AND(INDEX(Species!$H$2:$H$300,$R6)<>"",INDEX(Species!$H$2:$H$300,$R6)<>"SC"),"; LD50 route "&INDEX(Species!$H$2:$H$300,$R6),"")&IF(INDEX(Species!$I$2:$I$300,$R6)="D","; LD50 Tier D","")&IF(AND(ISNUMBER(INDEX(Species!$N$2:$N$300,$R6)),N(INDEX(Species!$N$2:$N$300,$R6))>1.5),"; yield sources differ "&TEXT(INDEX(Species!$N$2:$N$300,$R6),"0.0")&"x","")&IF(INDEX(Species!$M$2:$M$300,$R6)="D","; yield Tier D",""),3,300),"") | I6: =IFERROR(INDEX(Species!$S$2:$S$300,$R6)&"","") | J6: =IFERROR(INDEX(Species!$T$2:$T$300,$R6)&"","") | K6: =IFERROR(MEDIAN(0,100*(LOG10(ld_least)-LOG10(INDEX(Species!$G$2:$G$300,$R6)))/(LOG10(ld_least)-LOG10(ld_most)),100),"") -> 76.492898 | L6: =IFERROR(MEDIAN(0,100*(LOG10(INDEX(Species!$L$2:$L$300,$R6))-LOG10(y_min))/(LOG10(y_max)-LOG10(y_min)),100),"") -> 91.741525 | M6: =IFERROR(IF(ISNUMBER(INDEX(Species!$O$2:$O$300,$R6)),ord_floor+(ord_ceil-ord_floor)*(INDEX(Species!$O$2:$O$300,$R6)-1)/9,""),"") -> 27.777778 | N6: =IFERROR(IF(ISNUMBER(INDEX(Species!$P$2:$P$300,$R6)),ord_floor+(ord_ceil-ord_floor)*(INDEX(Species!$P$2:$P$300,$R6)-1)/4,""),"") -> 30 | O6: =IFERROR(IF(ISNUMBER(INDEX(onset_ord,MATCH(INDEX(Species!$Q$2:$Q$300,$R6),onset_labels,0))),ord_floor+(ord_ceil-ord_floor)*(IF(onset_dir="mortality",6-INDEX(onset_ord,MATCH(INDEX(Species!$Q$2:$Q$300,$R6),onset_labels,0)),INDEX(onset_ord,MATCH(INDEX(Species!$Q$2:$Q$300,$R6),onset_labels,0)))-1)/4,""),"") -> 90 | P6: =IFERROR(IF(ISNUMBER(INDEX(access_ord,MATCH(INDEX(Species!$R$2:$R$300,$R6),access_labels,0))),ord_floor+(ord_ceil-ord_floor)*(INDEX(access_ord,MATCH(INDEX(Species!$R$2:$R$300,$R6),access_labels,0))-1)/4,""),"") -> 30 | Q6: =ISNUMBER(M6)*(w_enc>0)+ISNUMBER(N6)*(w_bite>0)+ISNUMBER(O6)*(w_onset>0)+ISNUMBER(P6)*(w_access>0) -> 4 | R6: =IFERROR(MATCH($A6,Species!$A$2:$A$300,0),"") -> 2
A7: Hydrophis schistosus | B7: =IFERROR(INDEX(Species!$B$2:$B$300,$R7),"NOT IN SPECIES") -> Hook-nosed sea snake | C7: =IF(w_pot+w_qty<=0,"",IF(AND(OR(w_pot=0,ISNUMBER(K7)),OR(w_qty=0,ISNUMBER(L7))),(w_pot*N(K7)+w_qty*N(L7))/(w_pot*ISNUMBER(K7)+w_qty*ISNUMBER(L7)),IF(ISNUMBER(K7),"needs yield","needs LD50"))) -> 68.903046 | D7: =IF(ISNUMBER(C7),RANK(C7,$C$2:$C$300),"") -> 20 | E7: =IF(w_enc+w_bite+w_onset+w_access<=0,"",IF(Q7<min_dims,"insufficient data",(w_enc*N(M7)+w_bite*N(N7)+w_onset*N(O7)+w_access*N(P7))/(w_enc*ISNUMBER(M7)+w_bite*ISNUMBER(N7)+w_onset*ISNUMBER(O7)+w_access*ISNUMBER(P7)))) -> 25.384615 | F7: =IF(ISNUMBER(E7),RANK(E7,$E$2:$E$300),"") -> 84 | G7: =IFERROR(IF(OR(INDEX(Species!$I$2:$I$300,$R7)="",INDEX(Species!$M$2:$M$300,$R7)=""),"",CHAR(MAX(CODE(INDEX(Species!$I$2:$I$300,$R7)),CODE(INDEX(Species!$M$2:$M$300,$R7))))),"") -> C | H7: =IFERROR(MID(IF(AND(ISNUMBER(INDEX(Species!$J$2:$J$300,$R7)),N(INDEX(Species!$J$2:$J$300,$R7))>1.5),"; LD50 sources differ "&TEXT(INDEX(Species!$J$2:$J$300,$R7),"0.0")&"x","")&IF(AND(INDEX(Species!$H$2:$H$300,$R7)<>"",INDEX(Species!$H$2:$H$300,$R7)<>"SC"),"; LD50 route "&INDEX(Species!$H$2:$H$300,$R7),"")&IF(INDEX(Species!$I$2:$I$300,$R7)="D","; LD50 Tier D","")&IF(AND(ISNUMBER(INDEX(Species!$N$2:$N$300,$R7)),N(INDEX(Species!$N$2:$N$300,$R7))>1.5),"; yield sources differ "&TEXT(INDEX(Species!$N$2:$N$300,$R7),"0.0")&"x","")&IF(INDEX(Species!$M$2:$M$300,$R7)="D","; yield Tier D",""),3,300),"") -> LD50 sources differ 8.2x | I7: =IFERROR(INDEX(Species!$S$2:$S$300,$R7)&"","") | J7: =IFERROR(INDEX(Species!$T$2:$T$300,$R7)&"","") | K7: =IFERROR(MEDIAN(0,100*(LOG10(ld_least)-LOG10(INDEX(Species!$G$2:$G$300,$R7)))/(LOG10(ld_least)-LOG10(ld_most)),100),"") -> 73.606049 | L7: =IFERROR(MEDIAN(0,100*(LOG10(INDEX(Species!$L$2:$L$300,$R7))-LOG10(y_min))/(LOG10(y_max)-LOG10(y_min)),100),"") -> 64.200044 | M7: =IFERROR(IF(ISNUMBER(INDEX(Species!$O$2:$O$300,$R7)),ord_floor+(ord_ceil-ord_floor)*(INDEX(Species!$O$2:$O$300,$R7)-1)/9,""),"") -> 10 | N7: =IFERROR(IF(ISNUMBER(INDEX(Species!$P$2:$P$300,$R7)),ord_floor+(ord_ceil-ord_floor)*(INDEX(Species!$P$2:$P$300,$R7)-1)/4,""),"") -> 10 | O7: =IFERROR(IF(ISNUMBER(INDEX(onset_ord,MATCH(INDEX(Species!$Q$2:$Q$300,$R7),onset_labels,0))),ord_floor+(ord_ceil-ord_floor)*(IF(onset_dir="mortality",6-INDEX(onset_ord,MATCH(INDEX(Species!$Q$2:$Q$300,$R7),onset_labels,0)),INDEX(onset_ord,MATCH(INDEX(Species!$Q$2:$Q$300,$R7),onset_labels,0)))-1)/4,""),"") -> 50 | P7: =IFERROR(IF(ISNUMBER(INDEX(access_ord,MATCH(INDEX(Species!$R$2:$R$300,$R7),access_labels,0))),ord_floor+(ord_ceil-ord_floor)*(INDEX(access_ord,MATCH(INDEX(Species!$R$2:$R$300,$R7),access_labels,0))-1)/4,""),"") -> 50 | Q7: =ISNUMBER(M7)*(w_enc>0)+ISNUMBER(N7)*(w_bite>0)+ISNUMBER(O7)*(w_onset>0)+ISNUMBER(P7)*(w_access>0) -> 4 | R7: =IFERROR(MATCH($A7,Species!$A$2:$A$300,0),"") -> 4
A8: Dendroaspis polylepis | B8: =IFERROR(INDEX(Species!$B$2:$B$300,$R8),"NOT IN SPECIES") -> Black mamba | C8: =IF(w_pot+w_qty<=0,"",IF(AND(OR(w_pot=0,ISNUMBER(K8)),OR(w_qty=0,ISNUMBER(L8))),(w_pot*N(K8)+w_qty*N(L8))/(w_pot*ISNUMBER(K8)+w_qty*ISNUMBER(L8)),IF(ISNUMBER(K8),"needs yield","needs LD50"))) -> 81.340379 | D8: =IF(ISNUMBER(C8),RANK(C8,$C$2:$C$300),"") -> 6 | E8: =IF(w_enc+w_bite+w_onset+w_access<=0,"",IF(Q8<min_dims,"insufficient data",(w_enc*N(M8)+w_bite*N(N8)+w_onset*N(O8)+w_access*N(P8))/(w_enc*ISNUMBER(M8)+w_bite*ISNUMBER(N8)+w_onset*ISNUMBER(O8)+w_access*ISNUMBER(P8)))) -> 40.598291 | F8: =IF(ISNUMBER(E8),RANK(E8,$E$2:$E$300),"") -> 55 | G8: =IFERROR(IF(OR(INDEX(Species!$I$2:$I$300,$R8)="",INDEX(Species!$M$2:$M$300,$R8)=""),"",CHAR(MAX(CODE(INDEX(Species!$I$2:$I$300,$R8)),CODE(INDEX(Species!$M$2:$M$300,$R8))))),"") -> D | H8: =IFERROR(MID(IF(AND(ISNUMBER(INDEX(Species!$J$2:$J$300,$R8)),N(INDEX(Species!$J$2:$J$300,$R8))>1.5),"; LD50 sources differ "&TEXT(INDEX(Species!$J$2:$J$300,$R8),"0.0")&"x","")&IF(AND(INDEX(Species!$H$2:$H$300,$R8)<>"",INDEX(Species!$H$2:$H$300,$R8)<>"SC"),"; LD50 route "&INDEX(Species!$H$2:$H$300,$R8),"")&IF(INDEX(Species!$I$2:$I$300,$R8)="D","; LD50 Tier D","")&IF(AND(ISNUMBER(INDEX(Species!$N$2:$N$300,$R8)),N(INDEX(Species!$N$2:$N$300,$R8))>1.5),"; yield sources differ "&TEXT(INDEX(Species!$N$2:$N$300,$R8),"0.0")&"x","")&IF(INDEX(Species!$M$2:$M$300,$R8)="D","; yield Tier D",""),3,300),"") -> LD50 sources differ 6.4x; LD50 Tier D; yield sources differ 4.0x | I8: =IFERROR(INDEX(Species!$S$2:$S$300,$R8)&"","") | J8: =IFERROR(INDEX(Species!$T$2:$T$300,$R8)&"","") | K8: =IFERROR(MEDIAN(0,100*(LOG10(ld_least)-LOG10(INDEX(Species!$G$2:$G$300,$R8)))/(LOG10(ld_least)-LOG10(ld_most)),100),"") -> 95.278643 | L8: =IFERROR(MEDIAN(0,100*(LOG10(INDEX(Species!$L$2:$L$300,$R8))-LOG10(y_min))/(LOG10(y_max)-LOG10(y_min)),100),"") -> 67.402116 | M8: =IFERROR(IF(ISNUMBER(INDEX(Species!$O$2:$O$300,$R8)),ord_floor+(ord_ceil-ord_floor)*(INDEX(Species!$O$2:$O$300,$R8)-1)/9,""),"") -> 45.555556 | N8: =IFERROR(IF(ISNUMBER(INDEX(Species!$P$2:$P$300,$R8)),ord_floor+(ord_ceil-ord_floor)*(INDEX(Species!$P$2:$P$300,$R8)-1)/4,""),"") -> 70 | O8: =IFERROR(IF(ISNUMBER(INDEX(onset_ord,MATCH(INDEX(Species!$Q$2:$Q$300,$R8),onset_labels,0))),ord_floor+(ord_ceil-ord_floor)*(IF(onset_dir="mortality",6-INDEX(onset_ord,MATCH(INDEX(Species!$Q$2:$Q$300,$R8),onset_labels,0)),INDEX(onset_ord,MATCH(INDEX(Species!$Q$2:$Q$300,$R8),onset_labels,0)))-1)/4,""),"") -> 10 | P8: =IFERROR(IF(ISNUMBER(INDEX(access_ord,MATCH(INDEX(Species!$R$2:$R$300,$R8),access_labels,0))),ord_floor+(ord_ceil-ord_floor)*(INDEX(access_ord,MATCH(INDEX(Species!$R$2:$R$300,$R8),access_labels,0))-1)/4,""),"") -> 30 | Q8: =ISNUMBER(M8)*(w_enc>0)+ISNUMBER(N8)*(w_bite>0)+ISNUMBER(O8)*(w_onset>0)+ISNUMBER(P8)*(w_access>0) -> 4 | R8: =IFERROR(MATCH($A8,Species!$A$2:$A$300,0),"") -> 7
A9: Bitis arietans | B9: =IFERROR(INDEX(Species!$B$2:$B$300,$R9),"NOT IN SPECIES") -> Puff adder | C9: =IF(w_pot+w_qty<=0,"",IF(AND(OR(w_pot=0,ISNUMBER(K9)),OR(w_qty=0,ISNUMBER(L9))),(w_pot*N(K9)+w_qty*N(L9))/(w_pot*ISNUMBER(K9)+w_qty*ISNUMBER(L9)),IF(ISNUMBER(K9),"needs yield","needs LD50"))) -> 80.456325 | D9: =IF(ISNUMBER(C9),RANK(C9,$C$2:$C$300),"") -> 7 | E9: =IF(w_enc+w_bite+w_onset+w_access<=0,"",IF(Q9<min_dims,"insufficient data",(w_enc*N(M9)+w_bite*N(N9)+w_onset*N(O9)+w_access*N(P9))/(w_enc*ISNUMBER(M9)+w_bite*ISNUMBER(N9)+w_onset*ISNUMBER(O9)+w_access*ISNUMBER(P9)))) -> 72.735043 | F9: =IF(ISNUMBER(E9),RANK(E9,$E$2:$E$300),"") -> 3 | G9: =IFERROR(IF(OR(INDEX(Species!$I$2:$I$300,$R9)="",INDEX(Species!$M$2:$M$300,$R9)=""),"",CHAR(MAX(CODE(INDEX(Species!$I$2:$I$300,$R9)),CODE(INDEX(Species!$M$2:$M$300,$R9))))),"") -> C | H9: =IFERROR(MID(IF(AND(ISNUMBER(INDEX(Species!$J$2:$J$300,$R9)),N(INDEX(Species!$J$2:$J$300,$R9))>1.5),"; LD50 sources differ "&TEXT(INDEX(Species!$J$2:$J$300,$R9),"0.0")&"x","")&IF(AND(INDEX(Species!$H$2:$H$300,$R9)<>"",INDEX(Species!$H$2:$H$300,$R9)<>"SC"),"; LD50 route "&INDEX(Species!$H$2:$H$300,$R9),"")&IF(INDEX(Species!$I$2:$I$300,$R9)="D","; LD50 Tier D","")&IF(AND(ISNUMBER(INDEX(Species!$N$2:$N$300,$R9)),N(INDEX(Species!$N$2:$N$300,$R9))>1.5),"; yield sources differ "&TEXT(INDEX(Species!$N$2:$N$300,$R9),"0.0")&"x","")&IF(INDEX(Species!$M$2:$M$300,$R9)="D","; yield Tier D",""),3,300),"") | I9: =IFERROR(INDEX(Species!$S$2:$S$300,$R9)&"","") | J9: =IFERROR(INDEX(Species!$T$2:$T$300,$R9)&"","") | K9: =IFERROR(MEDIAN(0,100*(LOG10(ld_least)-LOG10(INDEX(Species!$G$2:$G$300,$R9)))/(LOG10(ld_least)-LOG10(ld_most)),100),"") -> 76.492898 | L9: =IFERROR(MEDIAN(0,100*(LOG10(INDEX(Species!$L$2:$L$300,$R9))-LOG10(y_min))/(LOG10(y_max)-LOG10(y_min)),100),"") -> 84.419752 | M9: =IFERROR(IF(ISNUMBER(INDEX(Species!$O$2:$O$300,$R9)),ord_floor+(ord_ceil-ord_floor)*(INDEX(Species!$O$2:$O$300,$R9)-1)/9,""),"") -> 81.111111 | N9: =IFERROR(IF(ISNUMBER(INDEX(Species!$P$2:$P$300,$R9)),ord_floor+(ord_ceil-ord_floor)*(INDEX(Species!$P$2:$P$300,$R9)-1)/4,""),"") -> 70 | O9: =IFERROR(IF(ISNUMBER(INDEX(onset_ord,MATCH(INDEX(Species!$Q$2:$Q$300,$R9),onset_labels,0))),ord_floor+(ord_ceil-ord_floor)*(IF(onset_dir="mortality",6-INDEX(onset_ord,MATCH(INDEX(Species!$Q$2:$Q$300,$R9),onset_labels,0)),INDEX(onset_ord,MATCH(INDEX(Species!$Q$2:$Q$300,$R9),onset_labels,0)))-1)/4,""),"") -> 90 | P9: =IFERROR(IF(ISNUMBER(INDEX(access_ord,MATCH(INDEX(Species!$R$2:$R$300,$R9),access_labels,0))),ord_floor+(ord_ceil-ord_floor)*(INDEX(access_ord,MATCH(INDEX(Species!$R$2:$R$300,$R9),access_labels,0))-1)/4,""),"") -> 30 | Q9: =ISNUMBER(M9)*(w_enc>0)+ISNUMBER(N9)*(w_bite>0)+ISNUMBER(O9)*(w_onset>0)+ISNUMBER(P9)*(w_access>0) -> 4 | R9: =IFERROR(MATCH($A9,Species!$A$2:$A$300,0),"") -> 6
A10: Naja kaouthia | B10: =IFERROR(INDEX(Species!$B$2:$B$300,$R10),"NOT IN SPECIES") -> Monocled cobra | C10: =IF(w_pot+w_qty<=0,"",IF(AND(OR(w_pot=0,ISNUMBER(K10)),OR(w_qty=0,ISNUMBER(L10))),(w_pot*N(K10)+w_qty*N(L10))/(w_pot*ISNUMBER(K10)+w_qty*ISNUMBER(L10)),IF(ISNUMBER(K10),"needs yield","needs LD50"))) -> 79.78889 | D10: =IF(ISNUMBER(C10),RANK(C10,$C$2:$C$300),"") -> 8 | E10: =IF(w_enc+w_bite+w_onset+w_access<=0,"",IF(Q10<min_dims,"insufficient data",(w_enc*N(M10)+w_bite*N(N10)+w_onset*N(O10)+w_access*N(P10))/(w_enc*ISNUMBER(M10)+w_bite*ISNUMBER(N10)+w_onset*ISNUMBER(O10)+w_access*ISNUMBER(P10)))) -> 47.435897 | F10: =IF(ISNUMBER(E10),RANK(E10,$E$2:$E$300),"") -> 32 | G10: =IFERROR(IF(OR(INDEX(Species!$I$2:$I$300,$R10)="",INDEX(Species!$M$2:$M$300,$R10)=""),"",CHAR(MAX(CODE(INDEX(Species!$I$2:$I$300,$R10)),CODE(INDEX(Species!$M$2:$M$300,$R10))))),"") -> C | H10: =IFERROR(MID(IF(AND(ISNUMBER(INDEX(Species!$J$2:$J$300,$R10)),N(INDEX(Species!$J$2:$J$300,$R10))>1.5),"; LD50 sources differ "&TEXT(INDEX(Species!$J$2:$J$300,$R10),"0.0")&"x","")&IF(AND(INDEX(Species!$H$2:$H$300,$R10)<>"",INDEX(Species!$H$2:$H$300,$R10)<>"SC"),"; LD50 route "&INDEX(Species!$H$2:$H$300,$R10),"")&IF(INDEX(Species!$I$2:$I$300,$R10)="D","; LD50 Tier D","")&IF(AND(ISNUMBER(INDEX(Species!$N$2:$N$300,$R10)),N(INDEX(Species!$N$2:$N$300,$R10))>1.5),"; yield sources differ "&TEXT(INDEX(Species!$N$2:$N$300,$R10),"0.0")&"x","")&IF(INDEX(Species!$M$2:$M$300,$R10)="D","; yield Tier D",""),3,300),"") -> LD50 route IP | I10: =IFERROR(INDEX(Species!$S$2:$S$300,$R10)&"","") | J10: =IFERROR(INDEX(Species!$T$2:$T$300,$R10)&"","") | K10: =IFERROR(MEDIAN(0,100*(LOG10(ld_least)-LOG10(INDEX(Species!$G$2:$G$300,$R10)))/(LOG10(ld_least)-LOG10(ld_most)),100),"") -> 67.836256 | L10: =IFERROR(MEDIAN(0,100*(LOG10(INDEX(Species!$L$2:$L$300,$R10))-LOG10(y_min))/(LOG10(y_max)-LOG10(y_min)),100),"") -> 91.741525 | M10: =IFERROR(IF(ISNUMBER(INDEX(Species!$O$2:$O$300,$R10)),ord_floor+(ord_ceil-ord_floor)*(INDEX(Species!$O$2:$O$300,$R10)-1)/9,""),"") -> 63.333333 | N10: =IFERROR(IF(ISNUMBER(INDEX(Species!$P$2:$P$300,$R10)),ord_floor+(ord_ceil-ord_floor)*(INDEX(Species!$P$2:$P$300,$R10)-1)/4,""),"") -> 50 | O10: =IFERROR(IF(ISNUMBER(INDEX(onset_ord,MATCH(INDEX(Species!$Q$2:$Q$300,$R10),onset_labels,0))),ord_floor+(ord_ceil-ord_floor)*(IF(onset_dir="mortality",6-INDEX(onset_ord,MATCH(INDEX(Species!$Q$2:$Q$300,$R10),onset_labels,0)),INDEX(onset_ord,MATCH(INDEX(Species!$Q$2:$Q$300,$R10),onset_labels,0)))-1)/4,""),"") -> 30 | P10: =IFERROR(IF(ISNUMBER(INDEX(access_ord,MATCH(INDEX(Species!$R$2:$R$300,$R10),access_labels,0))),ord_floor+(ord_ceil-ord_floor)*(INDEX(access_ord,MATCH(INDEX(Species!$R$2:$R$300,$R10),access_labels,0))-1)/4,""),"") -> 30 | Q10: =ISNUMBER(M10)*(w_enc>0)+ISNUMBER(N10)*(w_bite>0)+ISNUMBER(O10)*(w_onset>0)+ISNUMBER(P10)*(w_access>0) -> 4 | R10: =IFERROR(MATCH($A10,Species!$A$2:$A$300,0),"") -> 76
A11: Notechis scutatus | B11: =IFERROR(INDEX(Species!$B$2:$B$300,$R11),"NOT IN SPECIES") -> Tiger snake | C11: =IF(w_pot+w_qty<=0,"",IF(AND(OR(w_pot=0,ISNUMBER(K11)),OR(w_qty=0,ISNUMBER(L11))),(w_pot*N(K11)+w_qty*N(L11))/(w_pot*ISNUMBER(K11)+w_qty*ISNUMBER(L11)),IF(ISNUMBER(K11),"needs yield","needs LD50"))) -> 77.830754 | D11: =IF(ISNUMBER(C11),RANK(C11,$C$2:$C$300),"") -> 10 | E11: =IF(w_enc+w_bite+w_onset+w_access<=0,"",IF(Q11<min_dims,"insufficient data",(w_enc*N(M11)+w_bite*N(N11)+w_onset*N(O11)+w_access*N(P11))/(w_enc*ISNUMBER(M11)+w_bite*ISNUMBER(N11)+w_onset*ISNUMBER(O11)+w_access*ISNUMBER(P11)))) -> 37.521368 | F11: =IF(ISNUMBER(E11),RANK(E11,$E$2:$E$300),"") -> 63 | G11: =IFERROR(IF(OR(INDEX(Species!$I$2:$I$300,$R11)="",INDEX(Species!$M$2:$M$300,$R11)=""),"",CHAR(MAX(CODE(INDEX(Species!$I$2:$I$300,$R11)),CODE(INDEX(Species!$M$2:$M$300,$R11))))),"") -> C | H11: =IFERROR(MID(IF(AND(ISNUMBER(INDEX(Species!$J$2:$J$300,$R11)),N(INDEX(Species!$J$2:$J$300,$R11))>1.5),"; LD50 sources differ "&TEXT(INDEX(Species!$J$2:$J$300,$R11),"0.0")&"x","")&IF(AND(INDEX(Species!$H$2:$H$300,$R11)<>"",INDEX(Species!$H$2:$H$300,$R11)<>"SC"),"; LD50 route "&INDEX(Species!$H$2:$H$300,$R11),"")&IF(INDEX(Species!$I$2:$I$300,$R11)="D","; LD50 Tier D","")&IF(AND(ISNUMBER(INDEX(Species!$N$2:$N$300,$R11)),N(INDEX(Species!$N$2:$N$300,$R11))>1.5),"; yield sources differ "&TEXT(INDEX(Species!$N$2:$N$300,$R11),"0.0")&"x","")&IF(INDEX(Species!$M$2:$M$300,$R11)="D","; yield Tier D",""),3,300),"") | I11: =IFERROR(INDEX(Species!$S$2:$S$300,$R11)&"","") -> 0.4 (Australia 2005-2015, tiger snakes) | J11: =IFERROR(INDEX(Species!$T$2:$T$300,$R11)&"","") | K11: =IFERROR(MEDIAN(0,100*(LOG10(ld_least)-LOG10(INDEX(Species!$G$2:$G$300,$R11)))/(LOG10(ld_least)-LOG10(ld_most)),100),"") -> 79.612079 | L11: =IFERROR(MEDIAN(0,100*(LOG10(INDEX(Species!$L$2:$L$300,$R11))-LOG10(y_min))/(LOG10(y_max)-LOG10(y_min)),100),"") -> 76.049428 | M11: =IFERROR(IF(ISNUMBER(INDEX(Species!$O$2:$O$300,$R11)),ord_floor+(ord_ceil-ord_floor)*(INDEX(Species!$O$2:$O$300,$R11)-1)/9,""),"") -> 45.555556 | N11: =IFERROR(IF(ISNUMBER(INDEX(Species!$P$2:$P$300,$R11)),ord_floor+(ord_ceil-ord_floor)*(INDEX(Species!$P$2:$P$300,$R11)-1)/4,""),"") -> 50 | O11: =IFERROR(IF(ISNUMBER(INDEX(onset_ord,MATCH(INDEX(Species!$Q$2:$Q$300,$R11),onset_labels,0))),ord_floor+(ord_ceil-ord_floor)*(IF(onset_dir="mortality",6-INDEX(onset_ord,MATCH(INDEX(Species!$Q$2:$Q$300,$R11),onset_labels,0)),INDEX(onset_ord,MATCH(INDEX(Species!$Q$2:$Q$300,$R11),onset_labels,0)))-1)/4,""),"") -> 30 | P11: =IFERROR(IF(ISNUMBER(INDEX(access_ord,MATCH(INDEX(Species!$R$2:$R$300,$R11),access_labels,0))),ord_floor+(ord_ceil-ord_floor)*(INDEX(access_ord,MATCH(INDEX(Species!$R$2:$R$300,$R11),access_labels,0))-1)/4,""),"") -> 10 | Q11: =ISNUMBER(M11)*(w_enc>0)+ISNUMBER(N11)*(w_bite>0)+ISNUMBER(O11)*(w_onset>0)+ISNUMBER(P11)*(w_access>0) -> 4 | R11: =IFERROR(MATCH($A11,Species!$A$2:$A$300,0),"") -> 9
A12: Pseudonaja textilis | B12: =IFERROR(INDEX(Species!$B$2:$B$300,$R12),"NOT IN SPECIES") -> Eastern brown snake | C12: =IF(w_pot+w_qty<=0,"",IF(AND(OR(w_pot=0,ISNUMBER(K12)),OR(w_qty=0,ISNUMBER(L12))),(w_pot*N(K12)+w_qty*N(L12))/(w_pot*ISNUMBER(K12)+w_qty*ISNUMBER(L12)),IF(ISNUMBER(K12),"needs yield","needs LD50"))) -> 78.088751 | D12: =IF(ISNUMBER(C12),RANK(C12,$C$2:$C$300),"") -> 9 | E12: =IF(w_enc+w_bite+w_onset+w_access<=0,"",IF(Q12<min_dims,"insufficient data",(w_enc*N(M12)+w_bite*N(N12)+w_onset*N(O12)+w_access*N(P12))/(w_enc*ISNUMBER(M12)+w_bite*ISNUMBER(N12)+w_onset*ISNUMBER(O12)+w_access*ISNUMBER(P12)))) -> 55.811966 | F12: =IF(ISNUMBER(E12),RANK(E12,$E$2:$E$300),"") -> 14 | G12: =IFERROR(IF(OR(INDEX(Species!$I$2:$I$300,$R12)="",INDEX(Species!$M$2:$M$300,$R12)=""),"",CHAR(MAX(CODE(INDEX(Species!$I$2:$I$300,$R12)),CODE(INDEX(Species!$M$2:$M$300,$R12))))),"") -> C | H12: =IFERROR(MID(IF(AND(ISNUMBER(INDEX(Species!$J$2:$J$300,$R12)),N(INDEX(Species!$J$2:$J$300,$R12))>1.5),"; LD50 sources differ "&TEXT(INDEX(Species!$J$2:$J$300,$R12),"0.0")&"x","")&IF(AND(INDEX(Species!$H$2:$H$300,$R12)<>"",INDEX(Species!$H$2:$H$300,$R12)<>"SC"),"; LD50 route "&INDEX(Species!$H$2:$H$300,$R12),"")&IF(INDEX(Species!$I$2:$I$300,$R12)="D","; LD50 Tier D","")&IF(AND(ISNUMBER(INDEX(Species!$N$2:$N$300,$R12)),N(INDEX(Species!$N$2:$N$300,$R12))>1.5),"; yield sources differ "&TEXT(INDEX(Species!$N$2:$N$300,$R12),"0.0")&"x","")&IF(INDEX(Species!$M$2:$M$300,$R12)="D","; yield Tier D",""),3,300),"") | I12: =IFERROR(INDEX(Species!$S$2:$S$300,$R12)&"","") -> 1.7 (Australia 2005-2015, all brown snakes) | J12: =IFERROR(INDEX(Species!$T$2:$T$300,$R12)&"","") | K12: =IFERROR(MEDIAN(0,100*(LOG10(ld_least)-LOG10(INDEX(Species!$G$2:$G$300,$R12)))/(LOG10(ld_least)-LOG10(ld_most)),100),"") -> 94.215507 | L12: =IFERROR(MEDIAN(0,100*(LOG10(INDEX(Species!$L$2:$L$300,$R12))-LOG10(y_min))/(LOG10(y_max)-LOG10(y_min)),100),"") -> 61.961995 | M12: =IFERROR(IF(ISNUMBER(INDEX(Species!$O$2:$O$300,$R12)),ord_floor+(ord_ceil-ord_floor)*(INDEX(Species!$O$2:$O$300,$R12)-1)/9,""),"") -> 81.111111 | N12: =IFERROR(IF(ISNUMBER(INDEX(Species!$P$2:$P$300,$R12)),ord_floor+(ord_ceil-ord_floor)*(INDEX(Species!$P$2:$P$300,$R12)-1)/4,""),"") -> 90 | O12: =IFERROR(IF(ISNUMBER(INDEX(onset_ord,MATCH(INDEX(Species!$Q$2:$Q$300,$R12),onset_labels,0))),ord_floor+(ord_ceil-ord_floor)*(IF(onset_dir="mortality",6-INDEX(onset_ord,MATCH(INDEX(Species!$Q$2:$Q$300,$R12),onset_labels,0)),INDEX(onset_ord,MATCH(INDEX(Species!$Q$2:$Q$300,$R12),onset_labels,0)))-1)/4,""),"") -> 10 | P12: =IFERROR(IF(ISNUMBER(INDEX(access_ord,MATCH(INDEX(Species!$R$2:$R$300,$R12),access_labels,0))),ord_floor+(ord_ceil-ord_floor)*(INDEX(access_ord,MATCH(INDEX(Species!$R$2:$R$300,$R12),access_labels,0))-1)/4,""),"") -> 10 | Q12: =ISNUMBER(M12)*(w_enc>0)+ISNUMBER(N12)*(w_bite>0)+ISNUMBER(O12)*(w_onset>0)+ISNUMBER(P12)*(w_access>0) -> 4 | R12: =IFERROR(MATCH($A12,Species!$A$2:$A$300,0),"") -> 10
A13: Naja haje | B13: =IFERROR(INDEX(Species!$B$2:$B$300,$R13),"NOT IN SPECIES") -> Egyptian cobra | C13: =IF(w_pot+w_qty<=0,"",IF(AND(OR(w_pot=0,ISNUMBER(K13)),OR(w_qty=0,ISNUMBER(L13))),(w_pot*N(K13)+w_qty*N(L13))/(w_pot*ISNUMBER(K13)+w_qty*ISNUMBER(L13)),IF(ISNUMBER(K13),"needs yield","needs LD50"))) -> 76.623433 | D13: =IF(ISNUMBER(C13),RANK(C13,$C$2:$C$300),"") -> 11 | E13: =IF(w_enc+w_bite+w_onset+w_access<=0,"",IF(Q13<min_dims,"insufficient data",(w_enc*N(M13)+w_bite*N(N13)+w_onset*N(O13)+w_access*N(P13))/(w_enc*ISNUMBER(M13)+w_bite*ISNUMBER(N13)+w_onset*ISNUMBER(O13)+w_access*ISNUMBER(P13)))) -> 48.632479 | F13: =IF(ISNUMBER(E13),RANK(E13,$E$2:$E$300),"") -> 28 | G13: =IFERROR(IF(OR(INDEX(Species!$I$2:$I$300,$R13)="",INDEX(Species!$M$2:$M$300,$R13)=""),"",CHAR(MAX(CODE(INDEX(Species!$I$2:$I$300,$R13)),CODE(INDEX(Species!$M$2:$M$300,$R13))))),"") -> C | H13: =IFERROR(MID(IF(AND(ISNUMBER(INDEX(Species!$J$2:$J$300,$R13)),N(INDEX(Species!$J$2:$J$300,$R13))>1.5),"; LD50 sources differ "&TEXT(INDEX(Species!$J$2:$J$300,$R13),"0.0")&"x","")&IF(AND(INDEX(Species!$H$2:$H$300,$R13)<>"",INDEX(Species!$H$2:$H$300,$R13)<>"SC"),"; LD50 route "&INDEX(Species!$H$2:$H$300,$R13),"")&IF(INDEX(Species!$I$2:$I$300,$R13)="D","; LD50 Tier D","")&IF(AND(ISNUMBER(INDEX(Species!$N$2:$N$300,$R13)),N(INDEX(Species!$N$2:$N$300,$R13))>1.5),"; yield sources differ "&TEXT(INDEX(Species!$N$2:$N$300,$R13),"0.0")&"x","")&IF(INDEX(Species!$M$2:$M$300,$R13)="D","; yield Tier D",""),3,300),"") | I13: =IFERROR(INDEX(Species!$S$2:$S$300,$R13)&"","") | J13: =IFERROR(INDEX(Species!$T$2:$T$300,$R13)&"","") | K13: =IFERROR(MEDIAN(0,100*(LOG10(ld_least)-LOG10(INDEX(Species!$G$2:$G$300,$R13)))/(LOG10(ld_least)-LOG10(ld_most)),100),"") -> 70.921109 | L13: =IFERROR(MEDIAN(0,100*(LOG10(INDEX(Species!$L$2:$L$300,$R13))-LOG10(y_min))/(LOG10(y_max)-LOG10(y_min)),100),"") -> 82.325756 | M13: =IFERROR(IF(ISNUMBER(INDEX(Species!$O$2:$O$300,$R13)),ord_floor+(ord_ceil-ord_floor)*(INDEX(Species!$O$2:$O$300,$R13)-1)/9,""),"") -> 54.444444 | N13: =IFERROR(IF(ISNUMBER(INDEX(Species!$P$2:$P$300,$R13)),ord_floor+(ord_ceil-ord_floor)*(INDEX(Species!$P$2:$P$300,$R13)-1)/4,""),"") -> 70 | O13: =IFERROR(IF(ISNUMBER(INDEX(onset_ord,MATCH(INDEX(Species!$Q$2:$Q$300,$R13),onset_labels,0))),ord_floor+(ord_ceil-ord_floor)*(IF(onset_dir="mortality",6-INDEX(onset_ord,MATCH(INDEX(Species!$Q$2:$Q$300,$R13),onset_labels,0)),INDEX(onset_ord,MATCH(INDEX(Species!$Q$2:$Q$300,$R13),onset_labels,0)))-1)/4,""),"") -> 30 | P13: =IFERROR(IF(ISNUMBER(INDEX(access_ord,MATCH(INDEX(Species!$R$2:$R$300,$R13),access_labels,0))),ord_floor+(ord_ceil-ord_floor)*(INDEX(access_ord,MATCH(INDEX(Species!$R$2:$R$300,$R13),access_labels,0))-1)/4,""),"") -> 30 | Q13: =ISNUMBER(M13)*(w_enc>0)+ISNUMBER(N13)*(w_bite>0)+ISNUMBER(O13)*(w_onset>0)+ISNUMBER(P13)*(w_access>0) -> 4 | R13: =IFERROR(MATCH($A13,Species!$A$2:$A$300,0),"") -> 8
... A95: Vipera ammodytes | B95: =IFERROR(INDEX(Species!$B$2:$B$300,$R95),"NOT IN SPECIES") -> Nose-horned viper | C95: =IF(w_pot+w_qty<=0,"",IF(AND(OR(w_pot=0,ISNUMBER(K95)),OR(w_qty=0,ISNUMBER(L95))),(w_pot*N(K95)+w_qty*N(L95))/(w_pot*ISNUMBER(K95)+w_qty*ISNUMBER(L95)),IF(ISNUMBER(K95),"needs yield","needs LD50"))) -> 55.283576 | D95: =IF(ISNUMBER(C95),RANK(C95,$C$2:$C$300),"") -> 49 | E95: =IF(w_enc+w_bite+w_onset+w_access<=0,"",IF(Q95<min_dims,"insufficient data",(w_enc*N(M95)+w_bite*N(N95)+w_onset*N(O95)+w_access*N(P95))/(w_enc*ISNUMBER(M95)+w_bite*ISNUMBER(N95)+w_onset*ISNUMBER(O95)+w_access*ISNUMBER(P95)))) -> 54.786325 | F95: =IF(ISNUMBER(E95),RANK(E95,$E$2:$E$300),"") -> 16 | G95: =IFERROR(IF(OR(INDEX(Species!$I$2:$I$300,$R95)="",INDEX(Species!$M$2:$M$300,$R95)=""),"",CHAR(MAX(CODE(INDEX(Species!$I$2:$I$300,$R95)),CODE(INDEX(Species!$M$2:$M$300,$R95))))),"") -> C | H95: =IFERROR(MID(IF(AND(ISNUMBER(INDEX(Species!$J$2:$J$300,$R95)),N(INDEX(Species!$J$2:$J$300,$R95))>1.5),"; LD50 sources differ "&TEXT(INDEX(Species!$J$2:$J$300,$R95),"0.0")&"x","")&IF(AND(INDEX(Species!$H$2:$H$300,$R95)<>"",INDEX(Species!$H$2:$H$300,$R95)<>"SC"),"; LD50 route "&INDEX(Species!$H$2:$H$300,$R95),"")&IF(INDEX(Species!$I$2:$I$300,$R95)="D","; LD50 Tier D","")&IF(AND(ISNUMBER(INDEX(Species!$N$2:$N$300,$R95)),N(INDEX(Species!$N$2:$N$300,$R95))>1.5),"; yield sources differ "&TEXT(INDEX(Species!$N$2:$N$300,$R95),"0.0")&"x","")&IF(INDEX(Species!$M$2:$M$300,$R95)="D","; yield Tier D",""),3,300),"") | I95: =IFERROR(INDEX(Species!$S$2:$S$300,$R95)&"","") | J95: =IFERROR(INDEX(Species!$T$2:$T$300,$R95)&"","") | K95: =IFERROR(MEDIAN(0,100*(LOG10(ld_least)-LOG10(INDEX(Species!$G$2:$G$300,$R95)))/(LOG10(ld_least)-LOG10(ld_most)),100),"") -> 54.012031 | L95: =IFERROR(MEDIAN(0,100*(LOG10(INDEX(Species!$L$2:$L$300,$R95))-LOG10(y_min))/(LOG10(y_max)-LOG10(y_min)),100),"") -> 56.555121 | M95: =IFERROR(IF(ISNUMBER(INDEX(Species!$O$2:$O$300,$R95)),ord_floor+(ord_ceil-ord_floor)*(INDEX(Species!$O$2:$O$300,$R95)-1)/9,""),"") -> 54.444444 | N95: =IFERROR(IF(ISNUMBER(INDEX(Species!$P$2:$P$300,$R95)),ord_floor+(ord_ceil-ord_floor)*(INDEX(Species!$P$2:$P$300,$R95)-1)/4,""),"") -> 50 | O95: =IFERROR(IF(ISNUMBER(INDEX(onset_ord,MATCH(INDEX(Species!$Q$2:$Q$300,$R95),onset_labels,0))),ord_floor+(ord_ceil-ord_floor)*(IF(onset_dir="mortality",6-INDEX(onset_ord,MATCH(INDEX(Species!$Q$2:$Q$300,$R95),onset_labels,0)),INDEX(onset_ord,MATCH(INDEX(Species!$Q$2:$Q$300,$R95),onset_labels,0)))-1)/4,""),"") -> 90 | P95: =IFERROR(IF(ISNUMBER(INDEX(access_ord,MATCH(INDEX(Species!$R$2:$R$300,$R95),access_labels,0))),ord_floor+(ord_ceil-ord_floor)*(INDEX(access_ord,MATCH(INDEX(Species!$R$2:$R$300,$R95),access_labels,0))-1)/4,""),"") -> 10 | Q95: =ISNUMBER(M95)*(w_enc>0)+ISNUMBER(N95)*(w_bite>0)+ISNUMBER(O95)*(w_onset>0)+ISNUMBER(P95)*(w_access>0) -> 4 | R95: =IFERROR(MATCH($A95,Species!$A$2:$A$300,0),"") -> 88

Sheet Combined
A1: Scientific name | B1: Common name | C1: Other common names | D1: LD50 used (mg/kg) | E1: Yield max (mg) | F1: VENOM HAZARD (0-100) | G1: Encounter (10-90) | H1: Bite propensity (10-90) | I1: Onset (10-90) | J1: Antivenom access (10-90) | K1: HUMAN RISK (0-100) | L1: COMBINED (0-100) | M1: Combined rank | N1: Scores row | O1: Species row
A2: Daboia russelii | B2: =IFERROR(INDEX(Species!$B$2:$B$300,$O2),"NOT IN SPECIES") -> Russell's viper | C2: =IFERROR(INDEX(Species!$C$2:$C$300,$O2)&"","") -> Chain viper; Daboia | D2: =IFERROR(INDEX(Species!$G$2:$G$300,$O2),"") -> 0.03 | E2: =IFERROR(INDEX(Species!$L$2:$L$300,$O2),"") -> 250 | F2: =IFERROR(INDEX(Scores!$C$2:$C$300,$N2),"") -> 89.924543 | G2: =IFERROR(INDEX(Scores!$M$2:$M$300,$N2),"") -> 90 | H2: =IFERROR(INDEX(Scores!$N$2:$N$300,$N2),"") -> 90 | I2: =IFERROR(INDEX(Scores!$O$2:$O$300,$N2),"") -> 70 | J2: =IFERROR(INDEX(Scores!$P$2:$P$300,$N2),"") -> 10 | K2: =IFERROR(INDEX(Scores!$E$2:$E$300,$N2),"") -> 73.076923 | L2: =IF(w_haz+w_risk<=0,"",IF(AND(OR(w_haz=0,ISNUMBER(F2)),OR(w_risk=0,ISNUMBER(K2))),(w_haz*N(F2)+w_risk*N(K2))/(w_haz*ISNUMBER(F2)+w_risk*ISNUMBER(K2)),IF(ISNUMBER(F2),"needs Human Risk",IF(ISNUMBER(K2),"needs Venom Hazard","needs both")))) -> 81.500733 | M2: =IF(ISNUMBER(L2),RANK(L2,$L$2:$L$300),"") -> 1 | N2: =IFERROR(MATCH($A2,Scores!$A$2:$A$300,0),"") -> 1 | O2: =IFERROR(MATCH($A2,Species!$A$2:$A$300,0),"") -> 1
A3: Bitis arietans | B3: =IFERROR(INDEX(Species!$B$2:$B$300,$O3),"NOT IN SPECIES") -> Puff adder | C3: =IFERROR(INDEX(Species!$C$2:$C$300,$O3)&"","") | D3: =IFERROR(INDEX(Species!$G$2:$G$300,$O3),"") -> 0.14 | E3: =IFERROR(INDEX(Species!$L$2:$L$300,$O3),"") -> 350 | F3: =IFERROR(INDEX(Scores!$C$2:$C$300,$N3),"") -> 80.456325 | G3: =IFERROR(INDEX(Scores!$M$2:$M$300,$N3),"") -> 81.111111 | H3: =IFERROR(INDEX(Scores!$N$2:$N$300,$N3),"") -> 70 | I3: =IFERROR(INDEX(Scores!$O$2:$O$300,$N3),"") -> 90 | J3: =IFERROR(INDEX(Scores!$P$2:$P$300,$N3),"") -> 30 | K3: =IFERROR(INDEX(Scores!$E$2:$E$300,$N3),"") -> 72.735043 | L3: =IF(w_haz+w_risk<=0,"",IF(AND(OR(w_haz=0,ISNUMBER(F3)),OR(w_risk=0,ISNUMBER(K3))),(w_haz*N(F3)+w_risk*N(K3))/(w_haz*ISNUMBER(F3)+w_risk*ISNUMBER(K3)),IF(ISNUMBER(F3),"needs Human Risk",IF(ISNUMBER(K3),"needs Venom Hazard","needs both")))) -> 76.595684 | M3: =IF(ISNUMBER(L3),RANK(L3,$L$2:$L$300),"") -> 2 | N3: =IFERROR(MATCH($A3,Scores!$A$2:$A$300,0),"") -> 8 | O3: =IFERROR(MATCH($A3,Species!$A$2:$A$300,0),"") -> 6
A4: Echis carinatus | B4: =IFERROR(INDEX(Species!$B$2:$B$300,$O4),"NOT IN SPECIES") -> Saw-scaled viper | C4: =IFERROR(INDEX(Species!$C$2:$C$300,$O4)&"","") -> Indian saw-scaled viper | D4: =IFERROR(INDEX(Species!$G$2:$G$300,$O4),"") -> 0.15 | E4: =IFERROR(INDEX(Species!$L$2:$L$300,$O4),"") -> 70 | F4: =IFERROR(INDEX(Scores!$C$2:$C$300,$N4),"") -> 68.895557 | G4: =IFERROR(INDEX(Scores!$M$2:$M$300,$N4),"") -> 90 | H4: =IFERROR(INDEX(Scores!$N$2:$N$300,$N4),"") -> 90 | I4: =IFERROR(INDEX(Scores!$O$2:$O$300,$N4),"") -> 90 | J4: =IFERROR(INDEX(Scores!$P$2:$P$300,$N4),"") -> 10 | K4: =IFERROR(INDEX(Scores!$E$2:$E$300,$N4),"") -> 77.692308 | L4: =IF(w_haz+w_risk<=0,"",IF(AND(OR(w_haz=0,ISNUMBER(F4)),OR(w_risk=0,ISNUMBER(K4))),(w_haz*N(F4)+w_risk*N(K4))/(w_haz*ISNUMBER(F4)+w_risk*ISNUMBER(K4)),IF(ISNUMBER(F4),"needs Human Risk",IF(ISNUMBER(K4),"needs Venom Hazard","needs both")))) -> 73.293932 | M4: =IF(ISNUMBER(L4),RANK(L4,$L$2:$L$300),"") -> 3 | N4: =IFERROR(MATCH($A4,Scores!$A$2:$A$300,0),"") -> 22 | O4: =IFERROR(MATCH($A4,Species!$A$2:$A$300,0),"") -> 19
A5: Bothrops asper | B5: =IFERROR(INDEX(Species!$B$2:$B$300,$O5),"NOT IN SPECIES") -> Terciopelo | C5: =IFERROR(INDEX(Species!$C$2:$C$300,$O5)&"","") -> Fer-de-lance; Barba amarilla | D5: =IFERROR(INDEX(Species!$G$2:$G$300,$O5),"") -> 1.1 | E5: =IFERROR(INDEX(Species!$L$2:$L$300,$O5),"") -> 310 | F5: =IFERROR(INDEX(Scores!$C$2:$C$300,$N5),"") -> 60.826366 | G5: =IFERROR(INDEX(Scores!$M$2:$M$300,$N5),"") -> 81.111111 | H5: =IFERROR(INDEX(Scores!$N$2:$N$300,$N5),"") -> 90 | I5: =IFERROR(INDEX(Scores!$O$2:$O$300,$N5),"") -> 70 | J5: =IFERROR(INDEX(Scores!$P$2:$P$300,$N5),"") -> 30 | K5: =IFERROR(INDEX(Scores!$E$2:$E$300,$N5),"") -> 72.735043 | L5: =IF(w_haz+w_risk<=0,"",IF(AND(OR(w_haz=0,ISNUMBER(F5)),OR(w_risk=0,ISNUMBER(K5))),(w_haz*N(F5)+w_risk*N(K5))/(w_haz*ISNUMBER(F5)+w_risk*ISNUMBER(K5)),IF(ISNUMBER(F5),"needs Human Risk",IF(ISNUMBER(K5),"needs Venom Hazard","needs both")))) -> 66.780704 | M5: =IF(ISNUMBER(L5),RANK(L5,$L$2:$L$300),"") -> 5 | N5: =IFERROR(MATCH($A5,Scores!$A$2:$A$300,0),"") -> 34 | O5: =IFERROR(MATCH($A5,Species!$A$2:$A$300,0),"") -> 23
A6: Pseudonaja textilis | B6: =IFERROR(INDEX(Species!$B$2:$B$300,$O6),"NOT IN SPECIES") -> Eastern brown snake | C6: =IFERROR(INDEX(Species!$C$2:$C$300,$O6)&"","") -> Common brown snake | D6: =IFERROR(INDEX(Species!$G$2:$G$300,$O6),"") -> 0.053 | E6: =IFERROR(INDEX(Species!$L$2:$L$300,$O6),"") -> 67 | F6: =IFERROR(INDEX(Scores!$C$2:$C$300,$N6),"") -> 78.088751 | G6: =IFERROR(INDEX(Scores!$M$2:$M$300,$N6),"") -> 81.111111 | H6: =IFERROR(INDEX(Scores!$N$2:$N$300,$N6),"") -> 90 | I6: =IFERROR(INDEX(Scores!$O$2:$O$300,$N6),"") -> 10 | J6: =IFERROR(INDEX(Scores!$P$2:$P$300,$N6),"") -> 10 | K6: =IFERROR(INDEX(Scores!$E$2:$E$300,$N6),"") -> 55.811966 | L6: =IF(w_haz+w_risk<=0,"",IF(AND(OR(w_haz=0,ISNUMBER(F6)),OR(w_risk=0,ISNUMBER(K6))),(w_haz*N(F6)+w_risk*N(K6))/(w_haz*ISNUMBER(F6)+w_risk*ISNUMBER(K6)),IF(ISNUMBER(F6),"needs Human Risk",IF(ISNUMBER(K6),"needs Venom Hazard","needs both")))) -> 66.950359 | M6: =IF(ISNUMBER(L6),RANK(L6,$L$2:$L$300),"") -> 4 | N6: =IFERROR(MATCH($A6,Scores!$A$2:$A$300,0),"") -> 11 | O6: =IFERROR(MATCH($A6,Species!$A$2:$A$300,0),"") -> 10
A7: Bothrops atrox | B7: =IFERROR(INDEX(Species!$B$2:$B$300,$O7),"NOT IN SPECIES") -> Common lancehead | C7: =IFERROR(INDEX(Species!$C$2:$C$300,$O7)&"","") -> Fer-de-lance; Barba amarilla | D7: =IFERROR(INDEX(Species!$G$2:$G$300,$O7),"") -> 0.35 | E7: =IFERROR(INDEX(Species!$L$2:$L$300,$O7),"") -> 200 | F7: =IFERROR(INDEX(Scores!$C$2:$C$300,$N7),"") -> 68.296378 | G7: =IFERROR(INDEX(Scores!$M$2:$M$300,$N7),"") -> 72.222222 | H7: =IFERROR(INDEX(Scores!$N$2:$N$300,$N7),"") -> 70 | I7: =IFERROR(INDEX(Scores!$O$2:$O$300,$N7),"") -> 70 | J7: =IFERROR(INDEX(Scores!$P$2:$P$300,$N7),"") -> 30 | K7: =IFERROR(INDEX(Scores!$E$2:$E$300,$N7),"") -> 64.700855 | L7: =IF(w_haz+w_risk<=0,"",IF(AND(OR(w_haz=0,ISNUMBER(F7)),OR(w_risk=0,ISNUMBER(K7))),(w_haz*N(F7)+w_risk*N(K7))/(w_haz*ISNUMBER(F7)+w_risk*ISNUMBER(K7)),IF(ISNUMBER(F7),"needs Human Risk",IF(ISNUMBER(K7),"needs Venom Hazard","needs both")))) -> 66.498616 | M7: =IF(ISNUMBER(L7),RANK(L7,$L$2:$L$300),"") -> 6 | N7: =IFERROR(MATCH($A7,Scores!$A$2:$A$300,0),"") -> 23 | O7: =IFERROR(MATCH($A7,Species!$A$2:$A$300,0),"") -> 84
A8: Naja kaouthia | B8: =IFERROR(INDEX(Species!$B$2:$B$300,$O8),"NOT IN SPECIES") -> Monocled cobra | C8: =IFERROR(INDEX(Species!$C$2:$C$300,$O8)&"","") -> Monocellate cobra | D8: =IFERROR(INDEX(Species!$G$2:$G$300,$O8),"") -> 0.225 | E8: =IFERROR(INDEX(Species!$L$2:$L$300,$O8),"") -> 600 | F8: =IFERROR(INDEX(Scores!$C$2:$C$300,$N8),"") -> 79.78889 | G8: =IFERROR(INDEX(Scores!$M$2:$M$300,$N8),"") -> 63.333333 | H8: =IFERROR(INDEX(Scores!$N$2:$N$300,$N8),"") -> 50 | I8: =IFERROR(INDEX(Scores!$O$2:$O$300,$N8),"") -> 30 | J8: =IFERROR(INDEX(Scores!$P$2:$P$300,$N8),"") -> 30 | K8: =IFERROR(INDEX(Scores!$E$2:$E$300,$N8),"") -> 47.435897 | L8: =IF(w_haz+w_risk<=0,"",IF(AND(OR(w_haz=0,ISNUMBER(F8)),OR(w_risk=0,ISNUMBER(K8))),(w_haz*N(F8)+w_risk*N(K8))/(w_haz*ISNUMBER(F8)+w_risk*ISNUMBER(K8)),IF(ISNUMBER(F8),"needs Human Risk",IF(ISNUMBER(K8),"needs Venom Hazard","needs both")))) -> 63.612394 | M8: =IF(ISNUMBER(L8),RANK(L8,$L$2:$L$300),"") -> 7 | N8: =IFERROR(MATCH($A8,Scores!$A$2:$A$300,0),"") -> 9 | O8: =IFERROR(MATCH($A8,Species!$A$2:$A$300,0),"") -> 76
A9: Bitis gabonica | B9: =IFERROR(INDEX(Species!$B$2:$B$300,$O9),"NOT IN SPECIES") -> Gaboon viper | C9: =IFERROR(INDEX(Species!$C$2:$C$300,$O9)&"","") -> Gaboon adder; Butterfly adder | D9: =IFERROR(INDEX(Species!$G$2:$G$300,$O9),"") -> 0.14 | E9: =IFERROR(INDEX(Species!$L$2:$L$300,$O9),"") -> 600 | F9: =IFERROR(INDEX(Scores!$C$2:$C$300,$N9),"") -> 84.117211 | G9: =IFERROR(INDEX(Scores!$M$2:$M$300,$N9),"") -> 27.777778 | H9: =IFERROR(INDEX(Scores!$N$2:$N$300,$N9),"") -> 30 | I9: =IFERROR(INDEX(Scores!$O$2:$O$300,$N9),"") -> 90 | J9: =IFERROR(INDEX(Scores!$P$2:$P$300,$N9),"") -> 30 | K9: =IFERROR(INDEX(Scores!$E$2:$E$300,$N9),"") -> 42.991453 | L9: =IF(w_haz+w_risk<=0,"",IF(AND(OR(w_haz=0,ISNUMBER(F9)),OR(w_risk=0,ISNUMBER(K9))),(w_haz*N(F9)+w_risk*N(K9))/(w_haz*ISNUMBER(F9)+w_risk*ISNUMBER(K9)),IF(ISNUMBER(F9),"needs Human Risk",IF(ISNUMBER(K9),"needs Venom Hazard","needs both")))) -> 63.554332 | M9: =IF(ISNUMBER(L9),RANK(L9,$L$2:$L$300),"") -> 8 | N9: =IFERROR(MATCH($A9,Scores!$A$2:$A$300,0),"") -> 5 | O9: =IFERROR(MATCH($A9,Species!$A$2:$A$300,0),"") -> 2
A10: Naja oxiana | B10: =IFERROR(INDEX(Species!$B$2:$B$300,$O10),"NOT IN SPECIES") -> Caspian cobra | C10: =IFERROR(INDEX(Species!$C$2:$C$300,$O10)&"","") -> Central Asian cobra; Oxus cobra | D10: =IFERROR(INDEX(Species!$G$2:$G$300,$O10),"") -> 0.1 | E10: =IFERROR(INDEX(Species!$L$2:$L$300,$O10),"") -> 124 | F10: =IFERROR(INDEX(Scores!$C$2:$C$300,$N10),"") -> 76.478075 | G10: =IFERROR(INDEX(Scores!$M$2:$M$300,$N10),"") -> 63.333333 | H10: =IFERROR(INDEX(Scores!$N$2:$N$300,$N10),"") -> 50 | I10: =IFERROR(INDEX(Scores!$O$2:$O$300,$N10),"") -> 30 | J10: =IFERROR(INDEX(Scores!$P$2:$P$300,$N10),"") -> 50 | K10: =IFERROR(INDEX(Scores!$E$2:$E$300,$N10),"") -> 50.512821 | L10: =IF(w_haz+w_risk<=0,"",IF(AND(OR(w_haz=0,ISNUMBER(F10)),OR(w_risk=0,ISNUMBER(K10))),(w_haz*N(F10)+w_risk*N(K10))/(w_haz*ISNUMBER(F10)+w_risk*ISNUMBER(K10)),IF(ISNUMBER(F10),"needs Human Risk",IF(ISNUMBER(K10),"needs Venom Hazard","needs both")))) -> 63.495448 | M10: =IF(ISNUMBER(L10),RANK(L10,$L$2:$L$300),"") -> 9 | N10: =IFERROR(MATCH($A10,Scores!$A$2:$A$300,0),"") -> 13 | O10: =IFERROR(MATCH($A10,Species!$A$2:$A$300,0),"") -> 11
A11: Naja haje | B11: =IFERROR(INDEX(Species!$B$2:$B$300,$O11),"NOT IN SPECIES") -> Egyptian cobra | C11: =IFERROR(INDEX(Species!$C$2:$C$300,$O11)&"","") -> Asp | D11: =IFERROR(INDEX(Species!$G$2:$G$300,$O11),"") -> 0.19 | E11: =IFERROR(INDEX(Species!$L$2:$L$300,$O11),"") -> 300 | F11: =IFERROR(INDEX(Scores!$C$2:$C$300,$N11),"") -> 76.623433 | G11: =IFERROR(INDEX(Scores!$M$2:$M$300,$N11),"") -> 54.444444 | H11: =IFERROR(INDEX(Scores!$N$2:$N$300,$N11),"") -> 70 | I11: =IFERROR(INDEX(Scores!$O$2:$O$300,$N11),"") -> 30 | J11: =IFERROR(INDEX(Scores!$P$2:$P$300,$N11),"") -> 30 | K11: =IFERROR(INDEX(Scores!$E$2:$E$300,$N11),"") -> 48.632479 | L11: =IF(w_haz+w_risk<=0,"",IF(AND(OR(w_haz=0,ISNUMBER(F11)),OR(w_risk=0,ISNUMBER(K11))),(w_haz*N(F11)+w_risk*N(K11))/(w_haz*ISNUMBER(F11)+w_risk*ISNUMBER(K11)),IF(ISNUMBER(F11),"needs Human Risk",IF(ISNUMBER(K11),"needs Venom Hazard","needs both")))) -> 62.627956 | M11: =IF(ISNUMBER(L11),RANK(L11,$L$2:$L$300),"") -> 10 | N11: =IFERROR(MATCH($A11,Scores!$A$2:$A$300,0),"") -> 12 | O11: =IFERROR(MATCH($A11,Species!$A$2:$A$300,0),"") -> 8
A12: Bothrops jararacussu | B12: =IFERROR(INDEX(Species!$B$2:$B$300,$O12),"NOT IN SPECIES") -> Jararacussu | C12: =IFERROR(INDEX(Species!$C$2:$C$300,$O12)&"","") | D12: =IFERROR(INDEX(Species!$G$2:$G$300,$O12),"") -> 0.46 | E12: =IFERROR(INDEX(Species!$L$2:$L$300,$O12),"") -> 321 | F12: =IFERROR(INDEX(Scores!$C$2:$C$300,$N12),"") -> 69.016691 | G12: =IFERROR(INDEX(Scores!$M$2:$M$300,$N12),"") -> 45.555556 | H12: =IFERROR(INDEX(Scores!$N$2:$N$300,$N12),"") -> 70 | I12: =IFERROR(INDEX(Scores!$O$2:$O$300,$N12),"") -> 70 | J12: =IFERROR(INDEX(Scores!$P$2:$P$300,$N12),"") -> 30 | K12: =IFERROR(INDEX(Scores!$E$2:$E$300,$N12),"") -> 54.444444 | L12: =IF(w_haz+w_risk<=0,"",IF(AND(OR(w_haz=0,ISNUMBER(F12)),OR(w_risk=0,ISNUMBER(K12))),(w_haz*N(F12)+w_risk*N(K12))/(w_haz*ISNUMBER(F12)+w_risk*ISNUMBER(K12)),IF(ISNUMBER(F12),"needs Human Risk",IF(ISNUMBER(K12),"needs Venom Hazard","needs both")))) -> 61.730568 | M12: =IF(ISNUMBER(L12),RANK(L12,$L$2:$L$300),"") -> 11 | N12: =IFERROR(MATCH($A12,Scores!$A$2:$A$300,0),"") -> 18 | O12: =IFERROR(MATCH($A12,Species!$A$2:$A$300,0),"") -> 15
A13: Naja nigricollis | B13: =IFERROR(INDEX(Species!$B$2:$B$300,$O13),"NOT IN SPECIES") -> Black-necked spitting cobra | C13: =IFERROR(INDEX(Species!$C$2:$C$300,$O13)&"","") | D13: =IFERROR(INDEX(Species!$G$2:$G$300,$O13),"") -> 0.23 | E13: =IFERROR(INDEX(Species!$L$2:$L$300,$O13),"") -> 350 | F13: =IFERROR(INDEX(Scores!$C$2:$C$300,$N13),"") -> 75.927498 | G13: =IFERROR(INDEX(Scores!$M$2:$M$300,$N13),"") -> 63.333333 | H13: =IFERROR(INDEX(Scores!$N$2:$N$300,$N13),"") -> 50 | I13: =IFERROR(INDEX(Scores!$O$2:$O$300,$N13),"") -> 30 | J13: =IFERROR(INDEX(Scores!$P$2:$P$300,$N13),"") -> 30 | K13: =IFERROR(INDEX(Scores!$E$2:$E$300,$N13),"") -> 47.435897 | L13: =IF(w_haz+w_risk<=0,"",IF(AND(OR(w_haz=0,ISNUMBER(F13)),OR(w_risk=0,ISNUMBER(K13))),(w_haz*N(F13)+w_risk*N(K13))/(w_haz*ISNUMBER(F13)+w_risk*ISNUMBER(K13)),IF(ISNUMBER(F13),"needs Human Risk",IF(ISNUMBER(K13),"needs Venom Hazard","needs both")))) -> 61.681697 | M13: =IF(ISNUMBER(L13),RANK(L13,$L$2:$L$300),"") -> 13 | N13: =IFERROR(MATCH($A13,Scores!$A$2:$A$300,0),"") -> 14 | O13: =IFERROR(MATCH($A13,Species!$A$2:$A$300,0),"") -> 55
... A95: Tropidechis carinatus | B95: =IFERROR(INDEX(Species!$B$2:$B$300,$O95),"NOT IN SPECIES") -> Rough-scaled snake | C95: =IFERROR(INDEX(Species!$C$2:$C$300,$O95)&"","") | D95: =IFERROR(INDEX(Species!$G$2:$G$300,$O95),"") -> 1.36 | E95: =IFERROR(INDEX(Species!$L$2:$L$300,$O95),"") | F95: =IFERROR(INDEX(Scores!$C$2:$C$300,$N95),"") -> needs yield | G95: =IFERROR(INDEX(Scores!$M$2:$M$300,$N95),"") -> 36.666667 | H95: =IFERROR(INDEX(Scores!$N$2:$N$300,$N95),"") -> 90 | I95: =IFERROR(INDEX(Scores!$O$2:$O$300,$N95),"") -> 30 | J95: =IFERROR(INDEX(Scores!$P$2:$P$300,$N95),"") -> 10 | K95: =IFERROR(INDEX(Scores!$E$2:$E$300,$N95),"") -> 43.333333 | L95: =IF(w_haz+w_risk<=0,"",IF(AND(OR(w_haz=0,ISNUMBER(F95)),OR(w_risk=0,ISNUMBER(K95))),(w_haz*N(F95)+w_risk*N(K95))/(w_haz*ISNUMBER(F95)+w_risk*ISNUMBER(K95)),IF(ISNUMBER(F95),"needs Human Risk",IF(ISNUMBER(K95),"needs Venom Hazard","needs both")))) -> needs Venom Hazard | M95: =IF(ISNUMBER(L95),RANK(L95,$L$2:$L$300),"") | N95: =IFERROR(MATCH($A95,Scores!$A$2:$A$300,0),"") -> 93 | O95: =IFERROR(MATCH($A95,Species!$A$2:$A$300,0),"") -> 92

Sheet Species
A1: Scientific name | B1: Common name | C1: Other names | D1: Family | E1: Region | F1: Venom effects (from V:AC) | G1: LD50 used (mg/kg) | H1: LD50 route | I1: LD50 tier | J1: LD50 spread (x) | K1: Yield low / typical (mg) | L1: Yield max (mg) | M1: Yield tier | N1: Yield spread (x) | O1: Encounter (1-10) | P1: Bite propensity (1-5) | Q1: Onset (untreated) | R1: Antivenom access | S1: Annual deaths (documented) | T1: Case-fatality rate | U1: Notes | V1: Neurotoxic | W1: Hemotoxic (any) | X1: Procoagulant | Y1: Anticoagulant | Z1: Hemorrhagic | AA1: Cytotoxic | AB1: Myotoxic | AC1: Cardiotoxic | AD1: Venom effects source | AE1: Encounter reason
A2: Daboia russelii | B2: Russell's viper | C2: Chain viper; Daboia | D2: Viperidae | E2: South & Southeast Asia | F2: =IF(COUNTIF(V2:AC2,"Y")=0,"",UPPER(MID(IF(V2="Y","/neurotoxic","")&IF(W2="Y","/hemotoxic","")&IF(X2="Y","/procoagulant","")&IF(Y2="Y","/anticoagulant","")&IF(Z2="Y","/hemorrhagic","")&IF(AA2="Y","/cytotoxic","")&IF(AB2="Y","/myotoxic","")&IF(AC2="Y","/cardiotoxic",""),2,1))&MID(IF(V2="Y","/neurotoxic","")&IF(W2="Y","/hemotoxic","")&IF(X2="Y","/procoagulant","")&IF(Y2="Y","/anticoagulant","")&IF(Z2="Y","/hemorrhagic","")&IF(AA2="Y","/cytotoxic","")&IF(AB2="Y","/myotoxic","")&IF(AC2="Y","/cardiotoxic",""),3,200)) -> Hemotoxic/procoagulant | G2: =IFERROR(INDEX('LD50 Sources'!$C$2:$C$1000,MATCH($A2,'LD50 Sources'!$L$2:$L$1000,0)),"") -> 0.03 | H2: =IFERROR(INDEX('LD50 Sources'!$D$2:$D$1000,MATCH($A2,'LD50 Sources'!$L$2:$L$1000,0))&"","") -> SC | I2: =IFERROR(INDEX('LD50 Sources'!$H$2:$H$1000,MATCH($A2,'LD50 Sources'!$L$2:$L$1000,0))&"","") -> C | J2: =IF(COUNTIFS('LD50 Sources'!$A$2:$A$1000,$A2,'LD50 Sources'!$K$2:$K$1000,1)<2,"",ROUND(_xlfn.MAXIFS('LD50 Sources'!$C$2:$C$1000,'LD50 Sources'!$A$2:$A$1000,$A2,'LD50 Sources'!$K$2:$K$1000,1)/_xlfn.MINIFS('LD50 Sources'!$C$2:$C$1000,'LD50 Sources'!$A$2:$A$1000,$A2,'LD50 Sources'!$K$2:$K$1000,1),1)) | K2: =IFERROR(INDEX('Yield Sources'!$C$2:$C$1000,MATCH($A2,'Yield Sources'!$N$2:$N$1000,0)),"") -> 130 | L2: =IFERROR(INDEX('Yield Sources'!$D$2:$D$1000,MATCH($A2,'Yield Sources'!$N$2:$N$1000,0)),"") -> 250 | M2: =IFERROR(INDEX('Yield Sources'!$J$2:$J$1000,MATCH($A2,'Yield Sources'!$N$2:$N$1000,0))&"","") -> C | N2: =IF(COUNTIFS('Yield Sources'!$A$2:$A$1000,$A2,'Yield Sources'!$M$2:$M$1000,1)<2,"",ROUND(_xlfn.MAXIFS('Yield Sources'!$D$2:$D$1000,'Yield Sources'!$A$2:$A$1000,$A2,'Yield Sources'!$M$2:$M$1000,1)/_xlfn.MINIFS('Yield Sources'!$D$2:$D$1000,'Yield Sources'!$A$2:$A$1000,$A2,'Yield Sources'!$M$2:$M$1000,1),1)) | O2: 10 | P2: 5 | Q2: Moderate-slow (hours to days) | R2: Widely available | S2: =IFERROR(INDEX('Clinical Sources'!$M$2:$M$1000,MATCH($A2&"|Annual deaths",'Clinical Sources'!$N$2:$N$1000,0)),"") | T2: =IFERROR(INDEX('Clinical Sources'!$M$2:$M$1000,MATCH($A2&"|Case-fatality rate",'Clinical Sources'!$N$2:$N$1000,0)),"") | U2: Clinical: Coagulopathy, internal bleeding, kidney failure develop over hours to days; can still be rapidly fatal with a large envenomation. Antivenom: India. | W2: Y | X2: Y | AD2: Carried from v3.2 text; source needed | AE2: Very common in farmland and around villages across South Asia, where most bites happen.
A3: Bitis gabonica | B3: Gaboon viper | C3: Gaboon adder; Butterfly adder | D3: Viperidae | E3: West & Central Africa | F3: =IF(COUNTIF(V3:AC3,"Y")=0,"",UPPER(MID(IF(V3="Y","/neurotoxic","")&IF(W3="Y","/hemotoxic","")&IF(X3="Y","/procoagulant","")&IF(Y3="Y","/anticoagulant","")&IF(Z3="Y","/hemorrhagic","")&IF(AA3="Y","/cytotoxic","")&IF(AB3="Y","/myotoxic","")&IF(AC3="Y","/cardiotoxic",""),2,1))&MID(IF(V3="Y","/neurotoxic","")&IF(W3="Y","/hemotoxic","")&IF(X3="Y","/procoagulant","")&IF(Y3="Y","/anticoagulant","")&IF(Z3="Y","/hemorrhagic","")&IF(AA3="Y","/cytotoxic","")&IF(AB3="Y","/myotoxic","")&IF(AC3="Y","/cardiotoxic",""),3,200)) -> Hemotoxic/cytotoxic | G3: =IFERROR(INDEX('LD50 Sources'!$C$2:$C$1000,MATCH($A3,'LD50 Sources'!$L$2:$L$1000,0)),"") -> 0.14 | H3: =IFERROR(INDEX('LD50 Sources'!$D$2:$D$1000,MATCH($A3,'LD50 Sources'!$L$2:$L$1000,0))&"","") -> SC | I3: =IFERROR(INDEX('LD50 Sources'!$H$2:$H$1000,MATCH($A3,'LD50 Sources'!$L$2:$L$1000,0))&"","") -> C | J3: =IF(COUNTIFS('LD50 Sources'!$A$2:$A$1000,$A3,'LD50 Sources'!$K$2:$K$1000,1)<2,"",ROUND(_xlfn.MAXIFS('LD50 Sources'!$C$2:$C$1000,'LD50 Sources'!$A$2:$A$1000,$A3,'LD50 Sources'!$K$2:$K$1000,1)/_xlfn.MINIFS('LD50 Sources'!$C$2:$C$1000,'LD50 Sources'!$A$2:$A$1000,$A3,'LD50 Sources'!$K$2:$K$1000,1),1)) | K3: =IFERROR(INDEX('Yield Sources'!$C$2:$C$1000,MATCH($A3,'Yield Sources'!$N$2:$N$1000,0)),"") -> 350 | L3: =IFERROR(INDEX('Yield Sources'!$D$2:$D$1000,MATCH($A3,'Yield Sources'!$N$2:$N$1000,0)),"") -> 600 | M3: =IFERROR(INDEX('Yield Sources'!$J$2:$J$1000,MATCH($A3,'Yield Sources'!$N$2:$N$1000,0))&"","") -> C | N3: =IF(COUNTIFS('Yield Sources'!$A$2:$A$1000,$A3,'Yield Sources'!$M$2:$M$1000,1)<2,"",ROUND(_xlfn.MAXIFS('Yield Sources'!$D$2:$D$1000,'Yield Sources'!$A$2:$A$1000,$A3,'Yield Sources'!$M$2:$M$1000,1)/_xlfn.MINIFS('Yield Sources'!$D$2:$D$1000,'Yield Sources'!$A$2:$A$1000,$A3,'Yield Sources'!$M$2:$M$1000,1),1)) | O3: 3 | P3: 2 | Q3: Slow (24 h or more) | R3: Regional | S3: =IFERROR(INDEX('Clinical Sources'!$M$2:$M$1000,MATCH($A3&"|Annual deaths",'Clinical Sources'!$N$2:$N$1000,0)),"") | T3: =IFERROR(INDEX('Clinical Sources'!$M$2:$M$1000,MATCH($A3&"|Case-fatality rate",'Clinical Sources'!$N$2:$N$1000,0)),"") | U3: Clinical: Severe local tissue damage and shock develop over 1-2 days; massive envenomation can cause faster cardiovascular collapse. Antivenom: SAIMR polyvalent. | W3: Y | AA3: Y | AD3: Carried from v3.2 text; source needed | AE3: Forest-floor snake of West and Central Africa; well camouflaged and rarely met.
